Workbook

Sheet Sref & AR 1
A1: Trade Study Name: Planform Area and Aspect Ratio
A3: Flight Conditions for Trade Study
A4: Parameter | B4: Subsonic | C4: Transonic | D4: Supersonic
A5: Altitude (ft) in 500ft increments | B5: 35000 | C5: 35000 | D5: 0
A6: Density (slug/ft^3) | B6: {=_xlfn.XLOOKUP(B$5,STDATM!$A$3:$A$203,STDATM!$D$3:$D$203,NA,0,1)} -> 0.000736627 | C6: {=_xlfn.XLOOKUP(C$5,STDATM!$A$3:$A$203,STDATM!$D$3:$D$203,NA,0,1)} -> 0.000736627 | D6: {=_xlfn.XLOOKUP(D$5,STDATM!$A$3:$A$203,STDATM!$D$3:$D$203,NA,0,1)} -> 0.00237717
A7: Viscosity (lb*s/ft^2) | B7: {=_xlfn.XLOOKUP(B$5,STDATM!$A$3:$A$203,STDATM!$F$3:$F$203,NA,0,1)} -> 3.01681e-07 | C7: {=_xlfn.XLOOKUP(C$5,STDATM!$A$3:$A$203,STDATM!$F$3:$F$203,NA,0,1)} -> 3.01681e-07 | D7: {=_xlfn.XLOOKUP(D$5,STDATM!$A$3:$A$203,STDATM!$F$3:$F$203,NA,0,1)} -> 3.78456e-07
A8: Speed of Sound (ft/s) | B8: {=_xlfn.XLOOKUP(B$5,STDATM!$A$3:$A$203,STDATM!$E$3:$E$203,NA,0,1)} -> 972.885 | C8: {=_xlfn.XLOOKUP(C$5,STDATM!$A$3:$A$203,STDATM!$E$3:$E$203,NA,0,1)} -> 972.885 | D8: {=_xlfn.XLOOKUP(D$5,STDATM!$A$3:$A$203,STDATM!$E$3:$E$203,NA,0,1)} -> 1116.45
A9: Machs tested | B9: 0.75 | C9: 0.95 | D9: 2
A10: Velocity (ft/s) | B10: =B9*B$8 -> 729.66375 | C10: =C9*C$8 -> 924.24075 | D10: =D9*D$8 -> 2232.9
A11: Re | B11: =(B6*B10*$B$27)/B7 -> #VALUE! | C11: =(C6*C10*$B$27)/C7 -> #VALUE! | D11: =(D6*D10*$B$27)/D7 -> #VALUE!
A12: Angle of Attack Range | B12: -5 deg to 12 deg | C12: -5 deg to 12 deg | D12: -5 deg to 12 deg
A14: Aircraft Baseline Configuration for Trade Study (align with OpenVSP geometry component names)
A15: Overall Configuration Baseline | B15: JetSubmersible_can1
A16: Fuselage component version | B16: JetSubmersible_can1
A17: Tail component version | B17: JetSubmersible_can1
A18: Engine inlet version | B18: JetSubmersible_can1
A19: Wing version
A21: Design Variables held Constant for Trade Study
A22: Sweep | B22: Varies | C22: deg
A23: Taper | B23: 0.35
A24: t/c (airfoil) | B24: 0.3 | C24: NACA 0009
A25: Dihedral | B25: 0 | C25: deg
A26: Twist | B26: 0 | C26: deg
A27: Fuselage Length | B27: Varies | C27: ft
A28: Crew Weight | B28: 450 | C28: lb
A29: Fixed Payload | B29: 1000 | C29: lb
A30: Total Uninstalled Thrust | B30: 12200 | C30: lb
A32: Analysis Method / Models
A33: Aerodynamics Model | B33: VSPAERO - VLM Method, VSP - Parasite Drag (Blausius-Lam & Turb), VSP - Wave Drag (Whitcomb)
A34: Mission Sizing Model | B34: Raymer First Order Weight Estimation Method
A35: Performance Sizing Model | B35: Brandt, Whitford Constraint Analysis Method
A37: Trade Study Data Capture
B38: Variable 1 | C38: Variable 2 (Optional) | D38: Mission Analysis Critical Metrics | F38: Constraint Analysis Critical Metrics
A39: Test Case | B39: Sref | C39: AR | D39: Wo | E39: Wf or Wbatt | F39: Current DP W/S | G39: Current DP T/W | H39: W/S opt | I39: T/W opt | J39: Limiting Requirements
A40: 1.1 | B40: 650 | C40: 1.25 | D40: 16333.834 | E40: 3829.6068 | F40: 25.244349 | G40: 0.74350226
A41: 1.2 | B41: 600 | C41: 1.25 | D41: 15840.811 | E41: 3735.9138 | F41: 26.519628 | G41: 0.76672771
A42: 1.3 | B42: 550 | C42: 1.25 | D42: 15358.445 | E42: 3656.2161 | F42: 28.055083 | G42: 0.79065237
A43: 1.4 | B43: 500 | C43: 1.25 | D43: 14876.851 | E43: 3588.3445 | F43: 29.894613 | G43: 0.81620057
A44: 1.5 | B44: 450 | C44: 1.25 | D44: 14413.315 | E44: 3543.9505 | F44: 32.187041 | G44: 0.84229895
A45: 2.1 | B45: 650 | C45: 1.5 | D45: 16647.075 | E45: 3589.7699 | F45: 25.730229 | G45: 0.72946225
...

Sheet Trade Study 1
A1: Trade Study Name:
A3: Flight Conditions for Trade Study
A4: Parameter | B4: Subsonic | C4: Transonic | D4: Supersonic
A5: Altitude (ft) in 500ft increments | B5: 35000 | C5: 0 | D5: 0
A6: Density (slug/ft^3) | B6: {=_xlfn.XLOOKUP(B$5,STDATM!$A$3:$A$203,STDATM!$D$3:$D$203,NA,0,1)} -> 0.000736627 | C6: {=_xlfn.XLOOKUP(C$5,STDATM!$A$3:$A$203,STDATM!$D$3:$D$203,NA,0,1)} -> 0.00237717 | D6: {=_xlfn.XLOOKUP(D$5,STDATM!$A$3:$A$203,STDATM!$D$3:$D$203,NA,0,1)} -> 0.00237717
A7: Viscosity (lb*s/ft^2) | B7: {=_xlfn.XLOOKUP(B$5,STDATM!$A$3:$A$203,STDATM!$F$3:$F$203,NA,0,1)} -> 3.01681e-07 | C7: {=_xlfn.XLOOKUP(C$5,STDATM!$A$3:$A$203,STDATM!$F$3:$F$203,NA,0,1)} -> 3.78456e-07 | D7: {=_xlfn.XLOOKUP(D$5,STDATM!$A$3:$A$203,STDATM!$F$3:$F$203,NA,0,1)} -> 3.78456e-07
A8: Speed of Sound (ft/s) | B8: {=_xlfn.XLOOKUP(B$5,STDATM!$A$3:$A$203,STDATM!$E$3:$E$203,NA,0,1)} -> 972.885 | C8: {=_xlfn.XLOOKUP(C$5,STDATM!$A$3:$A$203,STDATM!$E$3:$E$203,NA,0,1)} -> 1116.45 | D8: {=_xlfn.XLOOKUP(D$5,STDATM!$A$3:$A$203,STDATM!$E$3:$E$203,NA,0,1)} -> 1116.45
A9: Machs tested | B9: 0.75 | C9: 1.05 | D9: 2
A10: Velocity (ft/s) | B10: =B9*B$8 -> 729.66375 | C10: =C9*C$8 -> 1172.2725 | D10: =D9*D$8 -> 2232.9
A11: Re | B11: =(B6*B10*$B$27)/B7 -> #VALUE! | C11: =(C6*C10*$B$27)/C7 -> #VALUE! | D11: =(D6*D10*$B$27)/D7 -> #VALUE!
A12: Angle of Attack Range | B12: -5 deg to 12 deg | C12: -5 deg to 12 deg | D12: -5 deg to 12 deg
A14: Aircraft Baseline Configuration for Trade Study (align with OpenVSP geometry component names)
A15: Overall Configuration Baseline | B15: Dash 1.0 | C15: Keep close tabs on iteration version for your aircraft as you go through your trade study iterations!
A16: Fuselage component version
A17: Tail component version
A18: Engine inlet version
A19: Wing version
A21: Design Variables held Constant for Trade Study
A22: Sweep | B22: Varies | C22: deg
A23: Taper | B23: 0.35
A24: t/c (airfoil) | B24: 0.3 | C24: NACA 0009
A25: Dihedral | B25: 0 | C25: deg
A26: Twist | B26: 0 | C26: deg
A27: Fuselage Length | B27: Varies | C27: ft
A28: Crew Weight | B28: 450 | C28: lb
A29: Fixed Payload | B29: 1000 | C29: lb
A30: Total Uninstalled Thrust | B30: 12200 | C30: lb
A32: Analysis Method / Models
A33: Aerodynamics Model | B33: VSPAERO - VLM Method, VSP - Parasite Drag (Blausius-Lam & Turb), VSP - Wave Drag (Whitcomb)
A34: Mission Sizing Model | B34: Raymer First Order Weight Estimation Method
A35: Performance Sizing Model | B35: Brandt, Whitford Constraint Analysis Method
A37: Trade Study Data Capture
B38: Variable 1 | C38: Variable 2 (Optional) | D38: Mission Analysis Critical Metrics | F38: Constraint Analysis Critical Metrics
A39: Test Case | D39: Wo | E39: Wf or Wbatt | F39: Current DP W/S | G39: Current DP T/W | H39: W/S opt | I39: T/W opt | J39: Limiting Requirements

Sheet Trade Study 2
A1: Trade Study Name:
A3: Flight Conditions for Trade Study
A4: Parameter | B4: Subsonic | C4: Transonic | D4: Supersonic
A5: Altitude (ft) in 500ft increments | B5: 0 | C5: 0 | D5: 0
A6: Density (slug/ft^3) | B6: {=_xlfn.XLOOKUP(B$5,STDATM!$A$3:$A$203,STDATM!$D$3:$D$203,NA,0,1)} -> 0.00237717 | C6: {=_xlfn.XLOOKUP(C$5,STDATM!$A$3:$A$203,STDATM!$D$3:$D$203,NA,0,1)} -> 0.00237717 | D6: {=_xlfn.XLOOKUP(D$5,STDATM!$A$3:$A$203,STDATM!$D$3:$D$203,NA,0,1)} -> 0.00237717
A7: Viscosity (lb*s/ft^2) | B7: {=_xlfn.XLOOKUP(B$5,STDATM!$A$3:$A$203,STDATM!$F$3:$F$203,NA,0,1)} -> 3.78456e-07 | C7: {=_xlfn.XLOOKUP(C$5,STDATM!$A$3:$A$203,STDATM!$F$3:$F$203,NA,0,1)} -> 3.78456e-07 | D7: {=_xlfn.XLOOKUP(D$5,STDATM!$A$3:$A$203,STDATM!$F$3:$F$203,NA,0,1)} -> 3.78456e-07
A8: Speed of Sound (ft/s) | B8: {=_xlfn.XLOOKUP(B$5,STDATM!$A$3:$A$203,STDATM!$E$3:$E$203,NA,0,1)} -> 1116.45 | C8: {=_xlfn.XLOOKUP(C$5,STDATM!$A$3:$A$203,STDATM!$E$3:$E$203,NA,0,1)} -> 1116.45 | D8: {=_xlfn.XLOOKUP(D$5,STDATM!$A$3:$A$203,STDATM!$E$3:$E$203,NA,0,1)} -> 1116.45
A9: Machs tested | B9: 0.5 | C9: 1.05 | D9: 2
A10: Velocity (ft/s) | B10: =B9*B$8 -> 558.225 | C10: =C9*C$8 -> 1172.2725 | D10: =D9*D$8 -> 2232.9
A11: Re | B11: =(B6*B10*$B$27)/B7 -> 1.2398421e+08 | C11: =(C6*C10*$B$27)/C7 -> 2.6036684e+08 | D11: =(D6*D10*$B$27)/D7 -> 4.9593685e+08
A12: Angle of Attack Range | B12: -5 deg to 12 deg | C12: -5 deg to 12 deg | D12: -5 deg to 12 deg
A14: Aircraft Baseline Configuration for Trade Study (align with OpenVSP geometry component names)
A15: Overall Configuration Baseline | B15: Dash 1.0 | C15: Keep close tabs on iteration version for your aircraft as you go through your trade study iterations!
A16: Fuselage component version
A17: Tail component version
A18: Engine inlet version
A19: Wing version
A21: Design Variables held Constant for Trade Study
A22: Sref | B22: 2500 | C22: ft^2
A23: Taper | B23: 0.1
A24: t/c (airfoil) | B24: 0.04 | C24: Biconvex
A25: Dihedral | B25: 0 | C25: deg
A26: Twist | B26: 0 | C26: deg
A27: MAC | B27: 35.36 | C27: ft | D27: (Actually varies w/ AR and taper, but using representative case just to estimate Re)
A28: No changes to other aircraft components
A32: Analysis Method / Models
A33: Aerodynamics Model | B33: VSPAERO - VLM Method, VSP - Parasite Drag (Blausius-Lam & Turb), VSP - Wave Drag (Whitcomb)
A34: Mission Sizing Model | B34: Raymer First Order Weight Estimation Method
A35: Performance Sizing Model | B35: Brandt, Whitford Constraint Analysis Method
A37: Trade Study Data Capture
B38: Variable 1 | C38: Variable 2 (Optional) | D38: Mission Analysis Critical Metrics | F38: Constraint Analysis Critical Metrics
A39: Test Case | D39: Wo | E39: Wf or Wbatt | F39: Current DP W/S | G39: Current DP T/W | H39: W/S opt | I39: T/W opt | J39: Limiting Requirements

Sheet STDATM
A1: Altitude | B1: Temperature | C1: Pressure | D1: Density | E1: Speed of sound | F1: Viscosity
A2: [ft] | B2: [Rankine] | C2: [pound-force/sq. foot] | D2: [slug/ft3] | E2: [ft/s] | F2: [lb.sec/ft^2]
A3: 0 | B3: 518.67 | C3: 2116.23 | D3: 0.00237717 | E3: 1116.45 | F3: 3.78456e-07
A4: 500 | B4: 516.887 | C4: 2078.27 | D4: 0.00234259 | E4: 1114.53 | F4: 3.77422e-07
A5: 1000 | B5: 515.104 | C5: 2040.86 | D5: 0.00230839 | E5: 1112.61 | F5: 3.76386e-07
A6: 1500 | B6: 513.321 | C6: 2004.01 | D6: 0.00227457 | E6: 1110.68 | F6: 3.75349e-07
A7: 2000 | B7: 511.538 | C7: 1967.69 | D7: 0.00224114 | E7: 1108.75 | F7: 3.7431e-07
A8: 2500 | B8: 509.755 | C8: 1931.91 | D8: 0.00220808 | E8: 1106.81 | F8: 3.7327e-07
A9: 3000 | B9: 507.972 | C9: 1896.65 | D9: 0.00217539 | E9: 1104.88 | F9: 3.72228e-07
A10: 3500 | B10: 506.188 | C10: 1861.92 | D10: 0.00214308 | E10: 1102.94 | F10: 3.71184e-07
A11: 4000 | B11: 504.405 | C11: 1827.71 | D11: 0.00211114 | E11: 1100.99 | F11: 3.70138e-07
A12: 4500 | B12: 502.622 | C12: 1794 | D12: 0.00207956 | E12: 1099.04 | F12: 3.6909e-07
A13: 5000 | B13: 500.839 | C13: 1760.8 | D13: 0.00204834 | E13: 1097.09 | F13: 3.68041e-07
A14: 5500 | B14: 499.056 | C14: 1728.1 | D14: 0.00201748 | E14: 1095.14 | F14: 3.66991e-07
... A203: 100000 | B203: 408.834 | C203: 22.7686 | D203: 3.24473e-05 | E203: 991.214 | F203: 3.11406e-07
